Workbook

Sheet Parc consolidé
A1: CHARROI AUTOMOBILE PERFECT LOGISTICS — PARC CONSOLIDÉ
A2: Perfect Logistics — consolidation des charrois CHEMAF, MUMI, KAMOA, KINGAKILA, SICOMINES — état au 15/10/2026 (dates relatives recalculées à l'ouverture). Réalisé par BELEJ-CONSULTING.
A3: N° | B3: Site | C3: N° ordre | D3: Désignation | E3: Marque | F3: Plaque | G3: N° châssis | H3: N° série | I3: Places | J3: Assureur | K3: N° police | L3: Émission | M3: Échéance | N3: Jours restants | O3: État assurance | P3: Statut | Q3: Anomalies / remarques | R3: Source
A4: 1 | B4: CHEMAF | C4: 076 | D4: HILUX | E4: TOYOTA | F4: 8128AB14 | G4: AHTKK8CD900684789 | M4: 46424 | N4: =IF(M4="","",M4-TODAY()) | O4: =IF(M4="","Non assuré / inconnu",IF(N4<0,"Expirée",IF(N4<=30,"Expire < 30 j",IF(N4<=120,"Expire < 4 mois","Valide")))) | P4: Non renseigné | R4: CHAROITS PERFECT LOGISTICS CHEMAF.pdf
A5: 2 | B5: CHEMAF | C5: 052 | D5: MAHINDRA | E5: MAHINDRA | F5: 6941AB14 | G5: MA1RD4VP2038654 | M5: 46424 | N5: =IF(M5="","",M5-TODAY()) | O5: =IF(M5="","Non assuré / inconnu",IF(N5<0,"Expirée",IF(N5<=30,"Expire < 30 j",IF(N5<=120,"Expire < 4 mois","Valide")))) | P5: Non renseigné | Q5: Châssis tronqué (15 car.) | R5: CHAROITS PERFECT LOGISTICS CHEMAF.pdf
A6: 3 | B6: CHEMAF | C6: 092 | D6: LOADER | E6: XCMG | G6: XUG0050GJPCB00056 | N6: =IF(M6="","",M6-TODAY()) | O6: =IF(M6="","Non assuré / inconnu",IF(N6<0,"Expirée",IF(N6<=30,"Expire < 30 j",IF(N6<=120,"Expire < 4 mois","Valide")))) | P6: Non renseigné | R6: CHAROITS PERFECT LOGISTICS CHEMAF.pdf
A7: 4 | B7: CHEMAF | C7: 032 | D7: GRADER | E7: BELL | F7: 6902AA14 | G7: 1DW770GXKBC639971 | N7: =IF(M7="","",M7-TODAY()) | O7: =IF(M7="","Non assuré / inconnu",IF(N7<0,"Expirée",IF(N7<=30,"Expire < 30 j",IF(N7<=120,"Expire < 4 mois","Valide")))) | P7: Non renseigné | R7: CHAROITS PERFECT LOGISTICS CHEMAF.pdf
A8: 5 | B8: CHEMAF | C8: C04 | D8: ROLLER | E8: BOMAG | G8: 961582991150 | N8: =IF(M8="","",M8-TODAY()) | O8: =IF(M8="","Non assuré / inconnu",IF(N8<0,"Expirée",IF(N8<=30,"Expire < 30 j",IF(N8<=120,"Expire < 4 mois","Valide")))) | P8: Non renseigné | R8: CHAROITS PERFECT LOGISTICS CHEMAF.pdf
A9: 6 | B9: CHEMAF | C9: 203 | D9: BUS | E9: TATA | F9: 6510AB14 | G9: MAT462271P5L00126 | M9: 46424 | N9: =IF(M9="","",M9-TODAY()) | O9: =IF(M9="","Non assuré / inconnu",IF(N9<0,"Expirée",IF(N9<=30,"Expire < 30 j",IF(N9<=120,"Expire < 4 mois","Valide")))) | P9: Non renseigné | Q9: DOUBLON : châssis = SICOMINES 203, plaque = SICOMINES n°10 | R9: CHAROITS PERFECT LOGISTICS CHEMAF.pdf
A10: 7 | B10: CHEMAF | C10: 017 | D10: WATER BOWSER | E10: HOWO | F10: 4397AM05 | G10: LZZ5BLSF9GN192244 | M10: 46424 | N10: =IF(M10="","",M10-TODAY()) | O10: =IF(M10="","Non assuré / inconnu",IF(N10<0,"Expirée",IF(N10<=30,"Expire < 30 j",IF(N10<=120,"Expire < 4 mois","Valide")))) | P10: Non renseigné | R10: CHAROITS PERFECT LOGISTICS CHEMAF.pdf
A11: 8 | B11: CHEMAF | C11: 016 | D11: WATER BOWSER | E11: HOWO | F11: 3567AK05 | G11: LZZ5BLSF1FN079600 | M11: 46424 | N11: =IF(M11="","",M11-TODAY()) | O11: =IF(M11="","Non assuré / inconnu",IF(N11<0,"Expirée",IF(N11<=30,"Expire < 30 j",IF(N11<=120,"Expire < 4 mois","Valide")))) | P11: Non renseigné | R11: CHAROITS PERFECT LOGISTICS CHEMAF.pdf
A12: 9 | B12: CHEMAF | C12: 105 | D12: FUEL BOWSER | E12: HOWO | F12: 6465AA24 | G12: LZZ5BLSF2RN279972 | M12: 46552 | N12: =IF(M12="","",M12-TODAY()) | O12: =IF(M12="","Non assuré / inconnu",IF(N12<0,"Expirée",IF(N12<=30,"Expire < 30 j",IF(N12<=120,"Expire < 4 mois","Valide")))) | P12: Non renseigné | R12: CHAROITS PERFECT LOGISTICS CHEMAF.pdf
A13: 10 | B13: MUMI | C13: 112 | D13: HILUX | E13: TOYOTA | F13: 7918AB14 | G13: AHTKK8CD600685527 | J13: Mayfair | K13: 26-005-0000019078 | M13: 46424 | N13: =IF(M13="","",M13-TODAY()) | O13: =IF(M13="","Non assuré / inconnu",IF(N13<0,"Expirée",IF(N13<=30,"Expire < 30 j",IF(N13<=120,"Expire < 4 mois","Valide")))) | P13: Opérationnel | R13: CHARROI ... MUMI SEPTEMBRE 2026 (PL-084)
A14: 11 | B14: MUMI | C14: 050 | D14: PICK UP | E14: MAHINDRA | F14: 7113AB14 | G14: MA1RD4VK2P2C32957 | J14: Mayfair | K14: 26-005-0000028486 | M14: 46630 | N14: =IF(M14="","",M14-TODAY()) | O14: =IF(M14="","Non assuré / inconnu",IF(N14<0,"Expirée",IF(N14<=30,"Expire < 30 j",IF(N14<=120,"Expire < 4 mois","Valide")))) | P14: En panne | Q14: DOUBLON : repris par erreur en SICOMINES n°18 | R14: CHARROI ... MUMI SEPTEMBRE 2026 (PL-084)
A15: 12 | B15: MUMI | C15: 106 | D15: LAND CRUISER | E15: TOYOTA | F15: 7239AN05 | G15: JTERB71J40075329 | J15: Mayfair | K15: 26-005-0000019109 | M15: 46605 | N15: =IF(M15="","",M15-TODAY()) | O15: =IF(M15="","Non assuré / inconnu",IF(N15<0,"Expirée",IF(N15<=30,"Expire < 30 j",IF(N15<=120,"Expire < 4 mois","Valide")))) | P15: Opérationnel | Q15: Châssis tronqué (16 car.) | R15: CHARROI ... MUMI SEPTEMBRE 2026 (PL-084)
A16: 13 | B16: MUMI | C16: 037 | D16: LAND CRUISER | E16: TOYOTA | F16: 4400AA14 | G16: JTERB71J000062222 | J16: Mayfair | K16: 26-005-0000028487 | M16: 46630 | N16: =IF(M16="","",M16-TODAY()) | O16: =IF(M16="","Non assuré / inconnu",IF(N16<0,"Expirée",IF(N16<=30,"Expire < 30 j",IF(N16<=120,"Expire < 4 mois","Valide")))) | P16: Opérationnel | Q16: Châssis corrigé (O → 0) | R16: CHARROI ... MUMI SEPTEMBRE 2026 (PL-084)
A17: 14 | B17: MUMI | C17: 107 | D17: HILUX | E17: TOYOTA | F17: 5905AB14 | G17: AHTDK9CD600975538 | N17: =IF(M17="","",M17-TODAY()) | O17: =IF(M17="","Non assuré / inconnu",IF(N17<0,"Expirée",IF(N17<=30,"Expire < 30 j",IF(N17<=120,"Expire < 4 mois","Valide")))) | P17: Opérationnel | Q17: Pas d'assurance | R17: CHARROI ... MUMI SEPTEMBRE 2026 (PL-084)
A18: 15 | B18: MUMI | C18: 085 | D18: HILUX | E18: TOYOTA | F18: 5904AB14 | G18: AHTDK9CD400975554 | K18: 26-005-0000019095 | N18: =IF(M18="","",M18-TODAY()) | O18: =IF(M18="","Non assuré / inconnu",IF(N18<0,"Expirée",IF(N18<=30,"Expire < 30 j",IF(N18<=120,"Expire < 4 mois","Valide")))) | P18: Opérationnel | Q18: Police sans échéance | R18: CHARROI ... MUMI SEPTEMBRE 2026 (PL-084)
A19: 16 | B19: MUMI | C19: 078 | D19: CAMION | E19: FAW | F19: 3072AB04 | G19: LFNFVXMU3MADA2748 | K19: 26-005-0000019127 | M19: 46424 | N19: =IF(M19="","",M19-TODAY()) | O19: =IF(M19="","Non assuré / inconnu",IF(N19<0,"Expirée",IF(N19<=30,"Expire < 30 j",IF(N19<=120,"Expire < 4 mois","Valide")))) | P19: Opérationnel | R19: CHARROI ... MUMI SEPTEMBRE 2026 (PL-084)
A20: 17 | B20: MUMI | C20: 090 | D20: CAMION | E20: HOWO | F20: 2468AB14 | G20: LZZ5EXSE3JN389827 | K20: 26-005-0000019126 | M20: 46424 | N20: =IF(M20="","",M20-TODAY()) | O20: =IF(M20="","Non assuré / inconnu",IF(N20<0,"Expirée",IF(N20<=30,"Expire < 30 j",IF(N20<=120,"Expire < 4 mois","Valide")))) | P20: Opérationnel | R20: CHARROI ... MUMI SEPTEMBRE 2026 (PL-084)
A21: 18 | B21: MUMI | C21: 068 | D21: CAMION | E21: HOWO | F21: 0153AC14 | G21: LZZ5ELSD8MN887509 | K21: 26-005-0000019073 | M21: 46424 | N21: =IF(M21="","",M21-TODAY()) | O21: =IF(M21="","Non assuré / inconnu",IF(N21<0,"Expirée",IF(N21<=30,"Expire < 30 j",IF(N21<=120,"Expire < 4 mois","Valide")))) | P21: Opérationnel | R21: CHARROI ... MUMI SEPTEMBRE 2026 (PL-084)
A22: 19 | B22: MUMI | C22: 057 | D22: CAMION | E22: HOWO | F22: 26667AB | G22: LZZ5ELSD9MN772790 | K22: 26-005-0000019128 | M22: 46424 | N22: =IF(M22="","",M22-TODAY()) | O22: =IF(M22="","Non assuré / inconnu",IF(N22<0,"Expirée",IF(N22<=30,"Expire < 30 j",IF(N22<=120,"Expire < 4 mois","Valide")))) | P22: Opérationnel | Q22: Plaque mal formée (2667AB14 ?) | R22: CHARROI ... MUMI SEPTEMBRE 2026 (PL-084)
A23: 20 | B23: MUMI | C23: 058 | D23: CAMION | E23: HOWO | F23: 2669AB14 | G23: LZZ5ELSD2MN772792 | K23: 26-005-0000019129 | M23: 46424 | N23: =IF(M23="","",M23-TODAY()) | O23: =IF(M23="","Non assuré / inconnu",IF(N23<0,"Expirée",IF(N23<=30,"Expire < 30 j",IF(N23<=120,"Expire < 4 mois","Valide")))) | P23: Opérationnel | R23: CHARROI ... MUMI SEPTEMBRE 2026 (PL-084)
A24: 21 | B24: MUMI | C24: 018 | D24: CAMION | E24: HOWO | F24: 2414AM05 | G24: LZZ5BLNF2HW232395 | N24: =IF(M24="","",M24-TODAY()) | O24: =IF(M24="","Non assuré / inconnu",IF(N24<0,"Expirée",IF(N24<=30,"Expire < 30 j",IF(N24<=120,"Expire < 4 mois","Valide")))) | P24: Non renseigné | Q24: Hors numérotation, statut absent | R24: CHARROI ... MUMI SEPTEMBRE 2026 (PL-084)
A25: 22 | B25: MUMI | C25: 024 | D25: CAMION | E25: HOWO | F25: 8816AA14 | G25: LZZ5BLNF5JD407689 | N25: =IF(M25="","",M25-TODAY()) | O25: =IF(M25="","Non assuré / inconnu",IF(N25<0,"Expirée",IF(N25<=30,"Expire < 30 j",IF(N25<=120,"Expire < 4 mois","Valide")))) | P25: Non renseigné | Q25: Hors numérotation, statut absent | R25: CHARROI ... MUMI SEPTEMBRE 2026 (PL-084)
A26: 23 | B26: MUMI | C26: 021 | D26: ADT | E26: KOMATSU | G26: KMTHM013CRD009670 | H26: 9670 | N26: =IF(M26="","",M26-TODAY()) | O26: =IF(M26="","Non assuré / inconnu",IF(N26<0,"Expirée",IF(N26<=30,"Expire < 30 j",IF(N26<=120,"Expire < 4 mois","Valide")))) | P26: Opérationnel | R26: CHARROI ... MUMI SEPTEMBRE 2026 (PL-084)
A27: 24 | B27: MUMI | C27: 022 | D27: ADT | E27: KOMATSU | G27: KMTHM013PRD009669 | H27: 9669 | N27: =IF(M27="","",M27-TODAY()) | O27: =IF(M27="","Non assuré / inconnu",IF(N27<0,"Expirée",IF(N27<=30,"Expire < 30 j",IF(N27<=120,"Expire < 4 mois","Valide")))) | P27: Opérationnel | R27: CHARROI ... MUMI SEPTEMBRE 2026 (PL-084)
A28: 25 | B28: MUMI | C28: 025 | D28: ADT | E28: KOMATSU | G28: KMTHM013EPD009504 | H28: 9504 | N28: =IF(M28="","",M28-TODAY()) | O28: =IF(M28="","Non assuré / inconnu",IF(N28<0,"Expirée",IF(N28<=30,"Expire < 30 j",IF(N28<=120,"Expire < 4 mois","Valide")))) | P28: Opérationnel | R28: CHARROI ... MUMI SEPTEMBRE 2026 (PL-084)
A29: 26 | B29: MUMI | C29: 06 | D29: ADT | E29: KOMATSU | G29: KMTHM013KRD009673 | H29: 9673 | N29: =IF(M29="","",M29-TODAY()) | O29: =IF(M29="","Non assuré / inconnu",IF(N29<0,"Expirée",IF(N29<=30,"Expire < 30 j",IF(N29<=120,"Expire < 4 mois","Valide")))) | P29: Opérationnel | Q29: N° proche de KAMOA 006 | R29: CHARROI ... MUMI SEPTEMBRE 2026 (PL-084)
A30: 27 | B30: MUMI | C30: 03 | D30: ADT | E30: KOMATSU | G30: KMTHM013KND009165 | H30: 9165 | N30: =IF(M30="","",M30-TODAY()) | O30: =IF(M30="","Non assuré / inconnu",IF(N30<0,"Expirée",IF(N30<=30,"Expire < 30 j",IF(N30<=120,"Expire < 4 mois","Valide")))) | P30: En panne | R30: CHARROI ... MUMI SEPTEMBRE 2026 (PL-084)
A31: 28 | B31: MUMI | C31: 05 | D31: ADT | E31: CAT | G31: CAT00745A3F601060 | N31: =IF(M31="","",M31-TODAY()) | O31: =IF(M31="","Non assuré / inconnu",IF(N31<0,"Expirée",IF(N31<=30,"Expire < 30 j",IF(N31<=120,"Expire < 4 mois","Valide")))) | P31: Opérationnel | Q31: N° en double (générateur 05) | R31: CHARROI ... MUMI SEPTEMBRE 2026 (PL-084)
A32: 29 | B32: MUMI | C32: 027 | D32: ROCK BREAKER | E32: KOMATSU | F32: IT2397 | G32: KMTPC247TLC082397 | H32: 2397 | J32: Mayfair | K32: 26-005-0000019058 | M32: 46424 | N32: =IF(M32="","",M32-TODAY()) | O32: =IF(M32="","Non assuré / inconnu",IF(N32<0,"Expirée",IF(N32<=30,"Expire < 30 j",IF(N32<=120,"Expire < 4 mois","Valide")))) | P32: En panne | Q32: Châssis corrigé (O → 0) | R32: CHARROI ... MUMI SEPTEMBRE 2026 (PL-084)
A33: 30 | B33: MUMI | C33: 038 | D33: EXCAVATOR | E33: KOMATSU | F33: IT1617 | G33: KMTPC247CJ081617 | H33: 1617 | J33: Mayfair | K33: 26-005-0000019103 | M33: 46424 | N33: =IF(M33="","",M33-TODAY()) | O33: =IF(M33="","Non assuré / inconnu",IF(N33<0,"Expirée",IF(N33<=30,"Expire < 30 j",IF(N33<=120,"Expire < 4 mois","Valide")))) | P33: En panne | Q33: Châssis corrigé (O → 0) | R33: CHARROI ... MUMI SEPTEMBRE 2026 (PL-084)
A34: 31 | B34: MUMI | C34: 081 | D34: EXCAVATOR | E34: KOMATSU | G34: KMTPC284ELC100121 | J34: Mayfair | K34: 26-005-0000019079 | M34: 46424 | N34: =IF(M34="","",M34-TODAY()) | O34: =IF(M34="","Non assuré / inconnu",IF(N34<0,"Expirée",IF(N34<=30,"Expire < 30 j",IF(N34<=120,"Expire < 4 mois","Valide")))) | P34: En panne | R34: CHARROI ... MUMI SEPTEMBRE 2026 (PL-084)
A35: 32 | B35: MUMI | C35: 094 | D35: EXCAVATOR | E35: KOMATSU | G35: KMTPC247ENC083565 | H35: IT3565 | J35: Mayfair | K35: 26-005-0000019084 | M35: 46424 | N35: =IF(M35="","",M35-TODAY()) | O35: =IF(M35="","Non assuré / inconnu",IF(N35<0,"Expirée",IF(N35<=30,"Expire < 30 j",IF(N35<=120,"Expire < 4 mois","Valide")))) | P35: En panne | Q35: Châssis corrigé (O → 0) | R35: CHARROI ... MUMI SEPTEMBRE 2026 (PL-084)
A36: 33 | B36: MUMI | C36: 084 | D36: EXCAVATOR | E36: VOLVO | G36: VCEC250DK00280513 | J36: Mayfair | K36: 26-005-0000019077 | M36: 46424 | N36: =IF(M36="","",M36-TODAY()) | O36: =IF(M36="","Non assuré / inconnu",IF(N36<0,"Expirée",IF(N36<=30,"Expire < 30 j",IF(N36<=120,"Expire < 4 mois","Valide")))) | P36: Opérationnel | R36: CHARROI ... MUMI SEPTEMBRE 2026 (PL-084)
A37: 34 | B37: MUMI | C37: 097 | D37: EXCAVATOR | E37: KOMATSU | G37: KMTPC284CLC00122 | N37: =IF(M37="","",M37-TODAY()) | O37: =IF(M37="","Non assuré / inconnu",IF(N37<0,"Expirée",IF(N37<=30,"Expire < 30 j",IF(N37<=120,"Expire < 4 mois","Valide")))) | P37: Opérationnel | Q37: Châssis tronqué (16 car.) | R37: CHARROI ... MUMI SEPTEMBRE 2026 (PL-084)
A38: 35 | B38: MUMI | C38: 109 | D38: EXCAVATOR | E38: KOMATSU | G38: P4BI0014 | N38: =IF(M38="","",M38-TODAY()) | O38: =IF(M38="","Non assuré / inconnu",IF(N38<0,"Expirée",IF(N38<=30,"Expire < 30 j",IF(N38<=120,"Expire < 4 mois","Valide")))) | P38: Opérationnel | Q38: Châssis incomplet | R38: CHARROI ... MUMI SEPTEMBRE 2026 (PL-084)
A39: 36 | B39: MUMI | C39: 900 | D39: EXCAVATOR | E39: CAT | G39: CAT0390FKGAY20180 | N39: =IF(M39="","",M39-TODAY()) | O39: =IF(M39="","Non assuré / inconnu",IF(N39<0,"Expirée",IF(N39<=30,"Expire < 30 j",IF(N39<=120,"Expire < 4 mois","Valide")))) | P39: Stand-by | R39: CHARROI ... MUMI SEPTEMBRE 2026 (PL-084)
A40: 37 | B40: MUMI | C40: 113 | D40: EXCAVATOR | E40: CAT | G40: CAT00395JSGD40070 | N40: =IF(M40="","",M40-TODAY()) | O40: =IF(M40="","Non assuré / inconnu",IF(N40<0,"Expirée",IF(N40<=30,"Expire < 30 j",IF(N40<=120,"Expire < 4 mois","Valide")))) | P40: Opérationnel | R40: CHARROI ... MUMI SEPTEMBRE 2026 (PL-084)
...

Sheet Synthèse
A1: SYNTHÈSE PAR SITE
A2: Perfect Logistics — consolidation des charrois CHEMAF, MUMI, KAMOA, KINGAKILA, SICOMINES — état au 15/10/2026 (dates relatives recalculées à l'ouverture). Réalisé par BELEJ-CONSULTING.
A4: Site | B4: Total engins | C4: Opérationnel | D4: En panne | E4: Stand-by | F4: Statut non renseigné | G4: Taux dispo. | H4: Assurance expirée | I4: Sans assurance
A5: CHEMAF | B5: =COUNTIF('Parc consolidé'!$B$4:$B$112,A5) | C5: =COUNTIFS('Parc consolidé'!$B$4:$B$112,A5,'Parc consolidé'!$P$4:$P$112,"Opérationnel") | D5: =COUNTIFS('Parc consolidé'!$B$4:$B$112,A5,'Parc consolidé'!$P$4:$P$112,"En panne") | E5: =COUNTIFS('Parc consolidé'!$B$4:$B$112,A5,'Parc consolidé'!$P$4:$P$112,"Stand-by") | F5: =COUNTIFS('Parc consolidé'!$B$4:$B$112,A5,'Parc consolidé'!$P$4:$P$112,"Non renseigné") | G5: =IF(B5-F5=0,"",C5/(B5-F5)) | H5: =COUNTIFS('Parc consolidé'!$B$4:$B$112,A5,'Parc consolidé'!$O$4:$O$112,"Expirée") | I5: =COUNTIFS('Parc consolidé'!$B$4:$B$112,A5,'Parc consolidé'!$O$4:$O$112,"Non assuré / inconnu")
A6: MUMI | B6: =COUNTIF('Parc consolidé'!$B$4:$B$112,A6) | C6: =COUNTIFS('Parc consolidé'!$B$4:$B$112,A6,'Parc consolidé'!$P$4:$P$112,"Opérationnel") | D6: =COUNTIFS('Parc consolidé'!$B$4:$B$112,A6,'Parc consolidé'!$P$4:$P$112,"En panne") | E6: =COUNTIFS('Parc consolidé'!$B$4:$B$112,A6,'Parc consolidé'!$P$4:$P$112,"Stand-by") | F6: =COUNTIFS('Parc consolidé'!$B$4:$B$112,A6,'Parc consolidé'!$P$4:$P$112,"Non renseigné") | G6: =IF(B6-F6=0,"",C6/(B6-F6)) | H6: =COUNTIFS('Parc consolidé'!$B$4:$B$112,A6,'Parc consolidé'!$O$4:$O$112,"Expirée") | I6: =COUNTIFS('Parc consolidé'!$B$4:$B$112,A6,'Parc consolidé'!$O$4:$O$112,"Non assuré / inconnu")
A7: KAMOA | B7: =COUNTIF('Parc consolidé'!$B$4:$B$112,A7) | C7: =COUNTIFS('Parc consolidé'!$B$4:$B$112,A7,'Parc consolidé'!$P$4:$P$112,"Opérationnel") | D7: =COUNTIFS('Parc consolidé'!$B$4:$B$112,A7,'Parc consolidé'!$P$4:$P$112,"En panne") | E7: =COUNTIFS('Parc consolidé'!$B$4:$B$112,A7,'Parc consolidé'!$P$4:$P$112,"Stand-by") | F7: =COUNTIFS('Parc consolidé'!$B$4:$B$112,A7,'Parc consolidé'!$P$4:$P$112,"Non renseigné") | G7: =IF(B7-F7=0,"",C7/(B7-F7)) | H7: =COUNTIFS('Parc consolidé'!$B$4:$B$112,A7,'Parc consolidé'!$O$4:$O$112,"Expirée") | I7: =COUNTIFS('Parc consolidé'!$B$4:$B$112,A7,'Parc consolidé'!$O$4:$O$112,"Non assuré / inconnu")
A8: KINGAKILA | B8: =COUNTIF('Parc consolidé'!$B$4:$B$112,A8) | C8: =COUNTIFS('Parc consolidé'!$B$4:$B$112,A8,'Parc consolidé'!$P$4:$P$112,"Opérationnel") | D8: =COUNTIFS('Parc consolidé'!$B$4:$B$112,A8,'Parc consolidé'!$P$4:$P$112,"En panne") | E8: =COUNTIFS('Parc consolidé'!$B$4:$B$112,A8,'Parc consolidé'!$P$4:$P$112,"Stand-by") | F8: =COUNTIFS('Parc consolidé'!$B$4:$B$112,A8,'Parc consolidé'!$P$4:$P$112,"Non renseigné") | G8: =IF(B8-F8=0,"",C8/(B8-F8)) | H8: =COUNTIFS('Parc consolidé'!$B$4:$B$112,A8,'Parc consolidé'!$O$4:$O$112,"Expirée") | I8: =COUNTIFS('Parc consolidé'!$B$4:$B$112,A8,'Parc consolidé'!$O$4:$O$112,"Non assuré / inconnu")
A9: SICOMINES | B9: =COUNTIF('Parc consolidé'!$B$4:$B$112,A9) | C9: =COUNTIFS('Parc consolidé'!$B$4:$B$112,A9,'Parc consolidé'!$P$4:$P$112,"Opérationnel") | D9: =COUNTIFS('Parc consolidé'!$B$4:$B$112,A9,'Parc consolidé'!$P$4:$P$112,"En panne") | E9: =COUNTIFS('Parc consolidé'!$B$4:$B$112,A9,'Parc consolidé'!$P$4:$P$112,"Stand-by") | F9: =COUNTIFS('Parc consolidé'!$B$4:$B$112,A9,'Parc consolidé'!$P$4:$P$112,"Non renseigné") | G9: =IF(B9-F9=0,"",C9/(B9-F9)) | H9: =COUNTIFS('Parc consolidé'!$B$4:$B$112,A9,'Parc consolidé'!$O$4:$O$112,"Expirée") | I9: =COUNTIFS('Parc consolidé'!$B$4:$B$112,A9,'Parc consolidé'!$O$4:$O$112,"Non assuré / inconnu")
A10: TOTAL | B10: =SUM(B5:B9) | C10: =SUM(C5:C9) | D10: =SUM(D5:D9) | E10: =SUM(E5:E9) | F10: =SUM(F5:F9) | G10: =IF(B10-F10=0,"",C10/(B10-F10)) | H10: =SUM(H5:H9) | I10: =SUM(I5:I9)
A11: Taux dispo. = opérationnels / engins dont le statut est renseigné (KINGAKILA et SICOMINES ne donnent aucun statut).
A13: RÉPARTITION PAR DÉSIGNATION
A14: Désignation | B14: CHEMAF | C14: MUMI | D14: KAMOA | E14: KINGAKILA | F14: SICOMINES | G14: Total
A15: BELL | B15: =COUNTIFS('Parc consolidé'!$D$4:$D$112,$A15,'Parc consolidé'!$B$4:$B$112,B$14) | C15: =COUNTIFS('Parc consolidé'!$D$4:$D$112,$A15,'Parc consolidé'!$B$4:$B$112,C$14) | D15: =COUNTIFS('Parc consolidé'!$D$4:$D$112,$A15,'Parc consolidé'!$B$4:$B$112,D$14) | E15: =COUNTIFS('Parc consolidé'!$D$4:$D$112,$A15,'Parc consolidé'!$B$4:$B$112,E$14) | F15: =COUNTIFS('Parc consolidé'!$D$4:$D$112,$A15,'Parc consolidé'!$B$4:$B$112,F$14) | G15: =SUM(B15:F15)
A16: BOMAG | B16: =COUNTIFS('Parc consolidé'!$D$4:$D$112,$A16,'Parc consolidé'!$B$4:$B$112,B$14) | C16: =COUNTIFS('Parc consolidé'!$D$4:$D$112,$A16,'Parc consolidé'!$B$4:$B$112,C$14) | D16: =COUNTIFS('Parc consolidé'!$D$4:$D$112,$A16,'Parc consolidé'!$B$4:$B$112,D$14) | E16: =COUNTIFS('Parc consolidé'!$D$4:$D$112,$A16,'Parc consolidé'!$B$4:$B$112,E$14) | F16: =COUNTIFS('Parc consolidé'!$D$4:$D$112,$A16,'Parc consolidé'!$B$4:$B$112,F$14) | G16: =SUM(B16:F16)
A17: CAT | B17: =COUNTIFS('Parc consolidé'!$D$4:$D$112,$A17,'Parc consolidé'!$B$4:$B$112,B$14) | C17: =COUNTIFS('Parc consolidé'!$D$4:$D$112,$A17,'Parc consolidé'!$B$4:$B$112,C$14) | D17: =COUNTIFS('Parc consolidé'!$D$4:$D$112,$A17,'Parc consolidé'!$B$4:$B$112,D$14) | E17: =COUNTIFS('Parc consolidé'!$D$4:$D$112,$A17,'Parc consolidé'!$B$4:$B$112,E$14) | F17: =COUNTIFS('Parc consolidé'!$D$4:$D$112,$A17,'Parc consolidé'!$B$4:$B$112,F$14) | G17: =SUM(B17:F17)
A18: CHL | B18: =COUNTIFS('Parc consolidé'!$D$4:$D$112,$A18,'Parc consolidé'!$B$4:$B$112,B$14) | C18: =COUNTIFS('Parc consolidé'!$D$4:$D$112,$A18,'Parc consolidé'!$B$4:$B$112,C$14) | D18: =COUNTIFS('Parc consolidé'!$D$4:$D$112,$A18,'Parc consolidé'!$B$4:$B$112,D$14) | E18: =COUNTIFS('Parc consolidé'!$D$4:$D$112,$A18,'Parc consolidé'!$B$4:$B$112,E$14) | F18: =COUNTIFS('Parc consolidé'!$D$4:$D$112,$A18,'Parc consolidé'!$B$4:$B$112,F$14) | G18: =SUM(B18:F18)
A19: FAW | B19: =COUNTIFS('Parc consolidé'!$D$4:$D$112,$A19,'Parc consolidé'!$B$4:$B$112,B$14) | C19: =COUNTIFS('Parc consolidé'!$D$4:$D$112,$A19,'Parc consolidé'!$B$4:$B$112,C$14) | D19: =COUNTIFS('Parc consolidé'!$D$4:$D$112,$A19,'Parc consolidé'!$B$4:$B$112,D$14) | E19: =COUNTIFS('Parc consolidé'!$D$4:$D$112,$A19,'Parc consolidé'!$B$4:$B$112,E$14) | F19: =COUNTIFS('Parc consolidé'!$D$4:$D$112,$A19,'Parc consolidé'!$B$4:$B$112,F$14) | G19: =SUM(B19:F19)
A20: FINLAY | B20: =COUNTIFS('Parc consolidé'!$D$4:$D$112,$A20,'Parc consolidé'!$B$4:$B$112,B$14) | C20: =COUNTIFS('Parc consolidé'!$D$4:$D$112,$A20,'Parc consolidé'!$B$4:$B$112,C$14) | D20: =COUNTIFS('Parc consolidé'!$D$4:$D$112,$A20,'Parc consolidé'!$B$4:$B$112,D$14) | E20: =COUNTIFS('Parc consolidé'!$D$4:$D$112,$A20,'Parc consolidé'!$B$4:$B$112,E$14) | F20: =COUNTIFS('Parc consolidé'!$D$4:$D$112,$A20,'Parc consolidé'!$B$4:$B$112,F$14) | G20: =SUM(B20:F20)
A21: GEN-LIGHT | B21: =COUNTIFS('Parc consolidé'!$D$4:$D$112,$A21,'Parc consolidé'!$B$4:$B$112,B$14) | C21: =COUNTIFS('Parc consolidé'!$D$4:$D$112,$A21,'Parc consolidé'!$B$4:$B$112,C$14) | D21: =COUNTIFS('Parc consolidé'!$D$4:$D$112,$A21,'Parc consolidé'!$B$4:$B$112,D$14) | E21: =COUNTIFS('Parc consolidé'!$D$4:$D$112,$A21,'Parc consolidé'!$B$4:$B$112,E$14) | F21: =COUNTIFS('Parc consolidé'!$D$4:$D$112,$A21,'Parc consolidé'!$B$4:$B$112,F$14) | G21: =SUM(B21:F21)
A22: HOWO | B22: =COUNTIFS('Parc consolidé'!$D$4:$D$112,$A22,'Parc consolidé'!$B$4:$B$112,B$14) | C22: =COUNTIFS('Parc consolidé'!$D$4:$D$112,$A22,'Parc consolidé'!$B$4:$B$112,C$14) | D22: =COUNTIFS('Parc consolidé'!$D$4:$D$112,$A22,'Parc consolidé'!$B$4:$B$112,D$14) | E22: =COUNTIFS('Parc consolidé'!$D$4:$D$112,$A22,'Parc consolidé'!$B$4:$B$112,E$14) | F22: =COUNTIFS('Parc consolidé'!$D$4:$D$112,$A22,'Parc consolidé'!$B$4:$B$112,F$14) | G22: =SUM(B22:F22)
A23: KOMATSU | B23: =COUNTIFS('Parc consolidé'!$D$4:$D$112,$A23,'Parc consolidé'!$B$4:$B$112,B$14) | C23: =COUNTIFS('Parc consolidé'!$D$4:$D$112,$A23,'Parc consolidé'!$B$4:$B$112,C$14) | D23: =COUNTIFS('Parc consolidé'!$D$4:$D$112,$A23,'Parc consolidé'!$B$4:$B$112,D$14) | E23: =COUNTIFS('Parc consolidé'!$D$4:$D$112,$A23,'Parc consolidé'!$B$4:$B$112,E$14) | F23: =COUNTIFS('Parc consolidé'!$D$4:$D$112,$A23,'Parc consolidé'!$B$4:$B$112,F$14) | G23: =SUM(B23:F23)
A24: MAHINDRA | B24: =COUNTIFS('Parc consolidé'!$D$4:$D$112,$A24,'Parc consolidé'!$B$4:$B$112,B$14) | C24: =COUNTIFS('Parc consolidé'!$D$4:$D$112,$A24,'Parc consolidé'!$B$4:$B$112,C$14) | D24: =COUNTIFS('Parc consolidé'!$D$4:$D$112,$A24,'Parc consolidé'!$B$4:$B$112,D$14) | E24: =COUNTIFS('Parc consolidé'!$D$4:$D$112,$A24,'Parc consolidé'!$B$4:$B$112,E$14) | F24: =COUNTIFS('Parc consolidé'!$D$4:$D$112,$A24,'Parc consolidé'!$B$4:$B$112,F$14) | G24: =SUM(B24:F24)
A25: SHANTUI | B25: =COUNTIFS('Parc consolidé'!$D$4:$D$112,$A25,'Parc consolidé'!$B$4:$B$112,B$14) | C25: =COUNTIFS('Parc consolidé'!$D$4:$D$112,$A25,'Parc consolidé'!$B$4:$B$112,C$14) | D25: =COUNTIFS('Parc consolidé'!$D$4:$D$112,$A25,'Parc consolidé'!$B$4:$B$112,D$14) | E25: =COUNTIFS('Parc consolidé'!$D$4:$D$112,$A25,'Parc consolidé'!$B$4:$B$112,E$14) | F25: =COUNTIFS('Parc consolidé'!$D$4:$D$112,$A25,'Parc consolidé'!$B$4:$B$112,F$14) | G25: =SUM(B25:F25)
A26: SINOTRUCK | B26: =COUNTIFS('Parc consolidé'!$D$4:$D$112,$A26,'Parc consolidé'!$B$4:$B$112,B$14) | C26: =COUNTIFS('Parc consolidé'!$D$4:$D$112,$A26,'Parc consolidé'!$B$4:$B$112,C$14) | D26: =COUNTIFS('Parc consolidé'!$D$4:$D$112,$A26,'Parc consolidé'!$B$4:$B$112,D$14) | E26: =COUNTIFS('Parc consolidé'!$D$4:$D$112,$A26,'Parc consolidé'!$B$4:$B$112,E$14) | F26: =COUNTIFS('Parc consolidé'!$D$4:$D$112,$A26,'Parc consolidé'!$B$4:$B$112,F$14) | G26: =SUM(B26:F26)
... A36: ZL50GN | B36: =COUNTIFS('Parc consolidé'!$D$4:$D$112,$A36,'Parc consolidé'!$B$4:$B$112,B$14) | C36: =COUNTIFS('Parc consolidé'!$D$4:$D$112,$A36,'Parc consolidé'!$B$4:$B$112,C$14) | D36: =COUNTIFS('Parc consolidé'!$D$4:$D$112,$A36,'Parc consolidé'!$B$4:$B$112,D$14) | E36: =COUNTIFS('Parc consolidé'!$D$4:$D$112,$A36,'Parc consolidé'!$B$4:$B$112,E$14) | F36: =COUNTIFS('Parc consolidé'!$D$4:$D$112,$A36,'Parc consolidé'!$B$4:$B$112,F$14) | G36: =SUM(B36:F36)
A39: ÉCHÉANCES D'ASSURANCE
A40: État | B40: CHEMAF | C40: MUMI | D40: KAMOA | E40: KINGAKILA | F40: SICOMINES | G40: Total
A41: Expirée | B41: =COUNTIFS('Parc consolidé'!$O$4:$O$112,$A41,'Parc consolidé'!$B$4:$B$112,B$40) | C41: =COUNTIFS('Parc consolidé'!$O$4:$O$112,$A41,'Parc consolidé'!$B$4:$B$112,C$40) | D41: =COUNTIFS('Parc consolidé'!$O$4:$O$112,$A41,'Parc consolidé'!$B$4:$B$112,D$40) | E41: =COUNTIFS('Parc consolidé'!$O$4:$O$112,$A41,'Parc consolidé'!$B$4:$B$112,E$40) | F41: =COUNTIFS('Parc consolidé'!$O$4:$O$112,$A41,'Parc consolidé'!$B$4:$B$112,F$40) | G41: =SUM(B41:F41)
A42: Expire < 30 j | B42: =COUNTIFS('Parc consolidé'!$O$4:$O$112,$A42,'Parc consolidé'!$B$4:$B$112,B$40) | C42: =COUNTIFS('Parc consolidé'!$O$4:$O$112,$A42,'Parc consolidé'!$B$4:$B$112,C$40) | D42: =COUNTIFS('Parc consolidé'!$O$4:$O$112,$A42,'Parc consolidé'!$B$4:$B$112,D$40) | E42: =COUNTIFS('Parc consolidé'!$O$4:$O$112,$A42,'Parc consolidé'!$B$4:$B$112,E$40) | F42: =COUNTIFS('Parc consolidé'!$O$4:$O$112,$A42,'Parc consolidé'!$B$4:$B$112,F$40) | G42: =SUM(B42:F42)
A43: Expire < 4 mois | B43: =COUNTIFS('Parc consolidé'!$O$4:$O$112,$A43,'Parc consolidé'!$B$4:$B$112,B$40) | C43: =COUNTIFS('Parc consolidé'!$O$4:$O$112,$A43,'Parc consolidé'!$B$4:$B$112,C$40) | D43: =COUNTIFS('Parc consolidé'!$O$4:$O$112,$A43,'Parc consolidé'!$B$4:$B$112,D$40) | E43: =COUNTIFS('Parc consolidé'!$O$4:$O$112,$A43,'Parc consolidé'!$B$4:$B$112,E$40) | F43: =COUNTIFS('Parc consolidé'!$O$4:$O$112,$A43,'Parc consolidé'!$B$4:$B$112,F$40) | G43: =SUM(B43:F43)
A44: Valide | B44: =COUNTIFS('Parc consolidé'!$O$4:$O$112,$A44,'Parc consolidé'!$B$4:$B$112,B$40) | C44: =COUNTIFS('Parc consolidé'!$O$4:$O$112,$A44,'Parc consolidé'!$B$4:$B$112,C$40) | D44: =COUNTIFS('Parc consolidé'!$O$4:$O$112,$A44,'Parc consolidé'!$B$4:$B$112,D$40) | E44: =COUNTIFS('Parc consolidé'!$O$4:$O$112,$A44,'Parc consolidé'!$B$4:$B$112,E$40) | F44: =COUNTIFS('Parc consolidé'!$O$4:$O$112,$A44,'Parc consolidé'!$B$4:$B$112,F$40) | G44: =SUM(B44:F44)
A45: Non assuré / inconnu | B45: =COUNTIFS('Parc consolidé'!$O$4:$O$112,$A45,'Parc consolidé'!$B$4:$B$112,B$40) | C45: =COUNTIFS('Parc consolidé'!$O$4:$O$112,$A45,'Parc consolidé'!$B$4:$B$112,C$40) | D45: =COUNTIFS('Parc consolidé'!$O$4:$O$112,$A45,'Parc consolidé'!$B$4:$B$112,D$40) | E45: =COUNTIFS('Parc consolidé'!$O$4:$O$112,$A45,'Parc consolidé'!$B$4:$B$112,E$40) | F45: =COUNTIFS('Parc consolidé'!$O$4:$O$112,$A45,'Parc consolidé'!$B$4:$B$112,F$40) | G45: =SUM(B45:F45)

Sheet Anomalies à corriger
A1: ANOMALIES À FAIRE VALIDER PAR LES SITES
A2: Perfect Logistics — consolidation des charrois CHEMAF, MUMI, KAMOA, KINGAKILA, SICOMINES — état au 15/10/2026 (dates relatives recalculées à l'ouverture). Réalisé par BELEJ-CONSULTING.
A4: N° | B4: Type | C4: Détail | D4: Action proposée | E4: Priorité
A5: 1 | B5: Assurance expirée | C5: Bus MARCOPOLO 216 et 217 (MUMI, SONAS) : échéance 14/10/2026 | D5: Renouveler immédiatement | E5: Critique
A6: 2 | B6: Assurance expirée | C6: Dozers 036 KOMATSU et 933 CAT (MUMI) : échéance 06/02/2026, même n° de police 19098 | D6: Vérifier : expirée ou coquille pour 2027 | E6: Critique
A7: 3 | B7: Engin sur 2 sites | C7: Châssis MAT462271P5L00896 : KINGAKILA 208 (7055AB14) et SICOMINES 206 (7284AB14) | D7: Identifier le bon site / la bonne plaque | E7: Haute
A8: 4 | B8: Engin sur 2 sites | C8: Châssis MAT462271S5L00864 : KINGAKILA 219 (0880AC14) et SICOMINES n°12 (0878AC14) | D8: Identifier le bon site / la bonne plaque | E8: Haute
A9: 5 | B9: Engin sur 2 sites | C9: Châssis MAT462271P5L00126 : CHEMAF 203 (6510AB14) et SICOMINES 203 (7043AB14) ; plaque 6510AB14 aussi en SICOMINES n°10 | D9: Identifier le bon site / la bonne plaque | E9: Haute
A10: 6 | B10: Engin sur 2 sites | C10: Bus 1361AN05 : KAMOA bus 1 et SICOMINES n°17 | D10: Identifier le site d'affectation | E10: Haute
A11: 7 | B11: Engin sur 2 sites | C11: Bus 2940AF19 : KAMOA bus 201 et SICOMINES n°11 | D11: Identifier le site d'affectation | E11: Haute
A12: 8 | B12: Erreur de saisie | C12: SICOMINES n°18 (7113AB14) = pick-up MAHINDRA 050 de MUMI, saisi comme bus TATA | D12: Supprimer de la liste SICOMINES | E12: Haute
A13: 9 | B13: N° d'ordre en double | C13: KINGAKILA : 208 attribué à deux bus | D13: Attribuer un nouveau n° | E13: Haute
A14: 10 | B14: N° d'ordre en double | C14: MUMI : 05 (ADT CAT / générateur), 07 (crible / compacteur), 02 (générateur / compacteur) ; 05/005, 06/006 entre MUMI et KAMOA | D14: Adopter une codification unique (ex. préfixe site) | E14: Haute
A15: 11 | B15: N° d'ordre manquant | C15: 14 bus SICOMINES, 1 bus KINGAKILA, 1 HOWO KAMOA (3236AC14) | D15: Attribuer un n° d'ordre | E15: Moyenne
A16: 12 | B16: Châssis O/0 | C16: Lettre O saisie au lieu du chiffre 0 (MUMI 037, 027, 038, 094, 036 ; KINGAKILA / SICOMINES « P5LOO… », « HDLOO… ») | D16: Corrigé dans le parc consolidé — à confirmer | E16: Basse
... A21: 17 | B21: Statut manquant | C21: MUMI HOWO 018, 024, compacteurs 07 et 02 ; tout KINGAKILA et SICOMINES | D21: Compléter le statut | E21: Basse
