Workbook

Sheet Mode d'emploi
B1: PerfectMaint — Relevé terrain des indicateurs de carburant
B2: Parc : 108 engins (import d'octobre 2026), regroupés en 33 groupes d'engins identiques. Édité par BELEJ-CONSULTING.
B4: Pourquoi ce relevé
B5: L'encodeur ne saisira plus un pourcentage estimé, mais la graduation où se trouve l'aiguille (ex. « 2 » sur un indicateur à 4 tirets).
B6: PerfectMaint en déduit les litres à partir de la capacité du réservoir : 2 / 4 tirets avec un réservoir de 80 L = 40 L (50 %).
B7: Il faut donc connaître, pour chaque modèle d'engin : son type d'indicateur, son nombre de graduations et la capacité de son réservoir.
B9: Comment remplir
B10: 1. Onglet « Relevé par groupe » : une ligne par groupe d'engins identiques. Remplir UNIQUEMENT les cellules jaunes.
B11: • Modèle exact : lu sur la plaque constructeur ou la carte grise (ex. Land Cruiser 79, Hilux GD-6, Tata LP 1318).
B12: • Type d'indicateur : choisir dans la liste. Compter les graduations entre VIDE (E) et PLEIN (F) : E · ½ · F = 2 ; E · ¼ · ½ · ¾ · F = 4.
B13: • Capacité du réservoir en litres : notice constructeur ou plaque du réservoir. Réservoirs additionnels : capacité totale + remarque.
B14: • Joindre une photo du tableau de bord par groupe (nom du fichier = référence du groupe, ex. G01.jpg).
... B24: Ligne d'exemple (format attendu)

Sheet Relevé par groupe
A1: Relevé par groupe d'engins identiques — remplir les cellules jaunes
A2: Nb engins : calculé depuis l'onglet « Engins ». Graduations : nombre de tirets entre VIDE et PLEIN (laisser vide pour un affichage numérique).
A3: Réf. | B3: Groupe (catégorie · marque · type) | C3: Catégorie | D3: Marque | E3: Nb engins | F3: Sites | G3: Codes engins | H3: Modèle exact | I3: Type d'indicateur | J3: Nb graduations | K3: Capacité réservoir (L) | L3: Réservoir additionnel ? (Oui/Non) | M3: Photo tableau de bord prise ? (Oui/Non) | N3: Relevé par / date | O3: Remarques
A4: EX | B4: EXEMPLE — Véhicule léger · Toyota · LAND CRUISER | C4: Véhicule léger | D4: Toyota | F4: KAMOA | G4: (exemple) | H4: Land Cruiser 79 | I4: Aiguille 4 graduations (E · ¼ · ½ · ¾ · F) | J4: 4 | K4: 130 | L4: Oui | M4: Oui | N4: J. Kabeya 23/10/2026 | O4: Double réservoir 2 × 65 L (valeurs d'exemple, à remplacer par le relevé réel)
A5: G01 | B5: Bus · Tata · BUS 1318 | C5: Bus | D5: Tata | E5: =COUNTIF(Engins!$A:$A,A5) -> 28 | F5: KINGAKILA (8), SICOMINES (20) | G5: 208, 208-B, 218, 219, 220, 221, 223, 0981AC14, 5, 202, 203-B, 206, 207, 209, 210, 7331AB14, 6957AB14, 6510AB14, 2940AF19, 0878AC14, 0879AC14, 0256AC14, 3972AB14, 0165BA01, 1361AN05, 1070AB14, 1069AB14, 1068AB14
A6: G02 | B6: Bus · Tata · BUS | C6: Bus | D6: Tata | E6: =COUNTIF(Engins!$A:$A,A6) -> 3 | F6: CHEMAF (1), KAMOA (2) | G6: 203, 1, 201
A7: G03 | B7: Bus · Tata · BUS MARCOPOLO | C7: Bus | D7: Tata | E7: =COUNTIF(Engins!$A:$A,A7) -> 3 | F7: MUMI (3) | G7: 222, 216, 217
A8: G04 | B8: Bus · Yutong · BUS | C8: Bus | D8: Yutong | E8: =COUNTIF(Engins!$A:$A,A8) -> 2 | F8: KINGAKILA (2) | G8: 214, 215
A9: G05 | B9: Véhicule léger · Toyota · HILUX | C9: Véhicule léger | D9: Toyota | E9: =COUNTIF(Engins!$A:$A,A9) -> 8 | F9: CHEMAF (1), MUMI (3), KAMOA (4) | G9: 076, 112, 107, 085, 048, 077, 101, 102
A10: G06 | B10: Véhicule léger · Toyota · LAND CRUISER | C10: Véhicule léger | D10: Toyota | E10: =COUNTIF(Engins!$A:$A,A10) -> 6 | F10: MUMI (2), KAMOA (4) | G10: 106, 037, 030, 103, 006, 005
A11: G07 | B11: Véhicule léger · Mahindra · (non précisé) | C11: Véhicule léger | D11: Mahindra | E11: =COUNTIF(Engins!$A:$A,A11) -> 1 | F11: CHEMAF (1) | G11: 052
A12: G08 | B12: Véhicule léger · Mahindra · PICK UP | C12: Véhicule léger | D12: Mahindra | E12: =COUNTIF(Engins!$A:$A,A12) -> 1 | F12: MUMI (1) | G12: 050
A13: G09 | B13: Camion benne · HOWO · SINOTRUCK | C13: Camion benne | D13: HOWO | E13: =COUNTIF(Engins!$A:$A,A13) -> 8 | F13: KAMOA (8) | G13: 043, 045, 066, 067, 087, 088, 089, 3236AC14
A14: G10 | B14: Camion benne · HOWO · CAMION | C14: Camion benne | D14: HOWO | E14: =COUNTIF(Engins!$A:$A,A14) -> 6 | F14: MUMI (6) | G14: 090, 068, 057, 058, 018, 024
A15: G11 | B15: Camion benne · FAW · CAMION | C15: Camion benne | D15: FAW | E15: =COUNTIF(Engins!$A:$A,A15) -> 1 | F15: MUMI (1) | G15: 078
A16: G12 | B16: Camion citerne · HOWO · WATER BOWSER | C16: Camion citerne | D16: HOWO | E16: =COUNTIF(Engins!$A:$A,A16) -> 2 | F16: CHEMAF (2) | G16: 017, 016
... A37: G33 | B37: Groupe électrogène · Gen-Light · GENERATOR | C37: Groupe électrogène | D37: Gen-Light | E37: =COUNTIF(Engins!$A:$A,A37) -> 2 | F37: MUMI (2) | G37: 02, 05-B
B38: Total parc | E38: =SUM(E5:E37) -> 108

Sheet Engins
A1: Réf. groupe | B1: Code | C1: Site | D1: Catégorie | E1: Marque | F1: Désignation | G1: Plaque | H1: Châssis | I1: Différent du groupe ? (Oui/Non) | J1: Type d'indicateur (si différent) | K1: Nb graduations (si différent) | L1: Capacité réservoir L (si différente) | M1: Remarques
A2: G01 | B2: 0981AC14 | C2: KINGAKILA | D2: Bus | E2: Tata | F2: BUS TATA 1318 | G2: 0981AC14
A3: G01 | B3: 208 | C3: KINGAKILA | D3: Bus | E3: Tata | F3: BUS TATA 1318 208 | G3: 7055AB14 | H3: MAT462271P5L00896
A4: G01 | B4: 208-B | C4: KINGAKILA | D4: Bus | E4: Tata | F4: BUS TATA 1318 208 | G4: 7415AB14 | H4: MAT462271P5L00899
A5: G01 | B5: 218 | C5: KINGAKILA | D5: Bus | E5: Tata | F5: BUS TATA 1318 218 | G5: 0895AC14
A6: G01 | B6: 219 | C6: KINGAKILA | D6: Bus | E6: Tata | F6: BUS TATA 1318 219 | G6: 0880AC14 | H6: MAT462271S5L00864
A7: G01 | B7: 220 | C7: KINGAKILA | D7: Bus | E7: Tata | F7: BUS TATA 1318 220 | G7: 0877AC14 | H7: MAT462271S5L00728
A8: G01 | B8: 221 | C8: KINGAKILA | D8: Bus | E8: Tata | F8: BUS TATA 1318 221 | G8: 0729AC14
A9: G01 | B9: 223 | C9: KINGAKILA | D9: Bus | E9: Tata | F9: BUS TATA 1318 223 | G9: 1143AC14
A10: G01 | B10: 0165BA01 | C10: SICOMINES | D10: Bus | E10: Tata | F10: BUS TATA 1318 | G10: 0165BA01 | H10: MAT42271K0L00324
A11: G01 | B11: 0256AC14 | C11: SICOMINES | D11: Bus | E11: Tata | F11: BUS TATA 1318 | G11: 0256AC14 | H11: MAT42271P5L02066
A12: G01 | B12: 0878AC14 | C12: SICOMINES | D12: Bus | E12: Tata | F12: BUS TATA 1318 | G12: 0878AC14 | H12: MAT462271S5L00864
A13: G01 | B13: 0879AC14 | C13: SICOMINES | D13: Bus | E13: Tata | F13: BUS TATA 1318 | G13: 0879AC14 | H13: MAT42271P5L02343
A14: G01 | B14: 1068AB14 | C14: SICOMINES | D14: Bus | E14: Tata | F14: BUS TATA 1318 | G14: 1068AB14 | H14: MAT42271L0L00871
A15: G01 | B15: 1069AB14 | C15: SICOMINES | D15: Bus | E15: Tata | F15: BUS TATA 1318 | G15: 1069AB14 | H15: MAT42271L0L00889
A16: G01 | B16: 1070AB14 | C16: SICOMINES | D16: Bus | E16: Tata | F16: BUS TATA 1318 | G16: 1070AB14 | H16: MAT42271L0L00878
A17: G01 | B17: 1361AN05 | C17: SICOMINES | D17: Bus | E17: Tata | F17: BUS TATA 1318 | G17: 1361AN05 | H17: MAT42271HDL00600
A18: G01 | B18: 202 | C18: SICOMINES | D18: Bus | E18: Tata | F18: BUS TATA 1318 202 | G18: 6535AB14 | H18: MAT468271P5OO236
A19: G01 | B19: 203-B | C19: SICOMINES | D19: Bus | E19: Tata | F19: BUS TATA 1318 203 | G19: 7043AB14 | H19: MAT462271P5L00126
A20: G01 | B20: 206 | C20: SICOMINES | D20: Bus | E20: Tata | F20: BUS TATA 1318 206 | G20: 7284AB14 | H20: MAT462271P5L00896
A21: G01 | B21: 207 | C21: SICOMINES | D21: Bus | E21: Tata | F21: BUS TATA 1318 207 | G21: 7283AB14 | H21: MAT462271P5L00778
... A23: G01 | B23: 210 | C23: SICOMINES | D23: Bus | E23: Tata | F23: BUS TATA 1318 210 | G23: 7330AB14 | H23: MAT462271P5L00688
A24: G01 | B24: 2940AF19 | C24: SICOMINES | D24: Bus | E24: Tata | F24: BUS TATA 1318 | G24: 2940AF19
A25: G01 | B25: 3972AB14 | C25: SICOMINES | D25: Bus | E25: Tata | F25: BUS TATA 1318 | G25: 3972AB14 | H25: MAT42271P5L00167
A26: G01 | B26: 5 | C26: SICOMINES | D26: Bus | E26: Tata | F26: BUS TATA 1318 5 | G26: 1366AN06 | H26: MAT462271HDL00860
A27: G01 | B27: 6510AB14 | C27: SICOMINES | D27: Bus | E27: Tata | F27: BUS TATA 1318 | G27: 6510AB14
A28: G01 | B28: 6957AB14 | C28: SICOMINES | D28: Bus | E28: Tata | F28: BUS TATA 1318 | G28: 6957AB14
A29: G01 | B29: 7331AB14 | C29: SICOMINES | D29: Bus | E29: Tata | F29: BUS TATA 1318 | G29: 7331AB14 | H29: MAT462271P5L00670
A30: G02 | B30: 203 | C30: CHEMAF | D30: Bus | E30: Tata | F30: BUS TATA 203 | G30: 6510AB14 | H30: MAT462271P5L00126
A31: G02 | B31: 1 | C31: KAMOA | D31: Bus | E31: Tata | F31: BUS TATA 1 | G31: 1361AN05 | H31: MAT462271HDL00600
A32: G02 | B32: 201 | C32: KAMOA | D32: Bus | E32: Tata | F32: BUS TATA 201 | G32: 2940AF19 | H32: 462271EO1097
A33: G03 | B33: 216 | C33: MUMI | D33: Bus | E33: Tata | F33: BUS MARCOPOLO TATA 216 | G33: 9096AB14 | H33: MAT494051P8L00500
A34: G03 | B34: 217 | C34: MUMI | D34: Bus | E34: Tata | F34: BUS MARCOPOLO TATA 217 | G34: 9445AB14 | H34: MAT494051P7L00710
A35: G03 | B35: 222 | C35: MUMI | D35: Bus | E35: Tata | F35: BUS MARCOPOLO TATA 222 | G35: IT0095 | H35: MAT494051R8L0095
A36: G04 | B36: 214 | C36: KINGAKILA | D36: Bus | E36: Yutong | F36: BUS YUTONG 214 | G36: 6109AB14 | H36: LZYTATE22N1007059
A37: G04 | B37: 215 | C37: KINGAKILA | D37: Bus | E37: Yutong | F37: BUS YUTONG 215 | G37: 6107AB15 | H37: LZYTATE22N1007057
A38: G05 | B38: 076 | C38: CHEMAF | D38: Véhicule léger | E38: Toyota | F38: HILUX TOYOTA 076 | G38: 8128AB14 | H38: AHTKK8CD900684789
A39: G05 | B39: 048 | C39: KAMOA | D39: Véhicule léger | E39: Toyota | F39: HILUX TOYOTA 048 | G39: 7060AB14 | H39: ANTDK9CD200977125
A40: G05 | B40: 077 | C40: KAMOA | D40: Véhicule léger | E40: Toyota | F40: HILUX TOYOTA 077 | G40: 7727AB14 | H40: AHTKK8CD100685631
... A71: G13 | B71: 105 | C71: CHEMAF | D71: Camion citerne | E71: HOWO | F71: FUEL BOWSER HOWO 105 | G71: 6465AA24 | H71: LZZ5BLSF2RN279972
...

Sheet Listes
A1: Types d'indicateur (déjà créés dans PerfectMaint, sauf « Autre »)
A2: Aiguille 2 graduations (E · ½ · F)
A3: Aiguille 4 graduations (E · ¼ · ½ · ¾ · F)
A4: Aiguille 8 graduations
A5: Barres 8 segments
A6: Barres 10 segments
A7: Affichage numérique (%)
A8: Autre (préciser en remarque)
